Workbook
Name Slicer_Country: #N/A
Name Slicer_Event_Type: #N/A
Name Slicer_Market_Cap_Category: #N/A
Name Slicer_MonthYear: #N/A
Name Slicer_Sector: #N/A

Sheet Corporate_Actions_Data
A1: Announcement_Date | B1: MonthYear | C1: Company_Name | D1: Country | E1: Exchange | F1: Country-Exchange | G1: Event_Type | H1: Security_ID | I1: Identifier_Type | J1: Announcement_Source | K1: Sector | L1: Market_Cap_Category | M1: Event_Status
A2: 45860 | B2: =EOMONTH(Table1[[#This Row],[Announcement_Date]],0) -> 45869 | C2: Global Retail Corp | D2: Canada | E2: NASDAQ | F2: =CONCATENATE(D2,"-",E2) -> Canada-NASDAQ | G2: Merger & Acquisition | H2: ID925046 | I2: SEDOL | J2: Press Release | K2: Finance | L2: Mid Cap | M2: Completed
A3: 46012 | B3: =EOMONTH(Table1[[#This Row],[Announcement_Date]],0) -> 46022 | C3: Quantum Pharma | D3: USA | E3: TSX | F3: =CONCATENATE(D3,"-",E3) -> USA-TSX | G3: Merger & Acquisition | H3: ID823220 | I3: CUSIP | J3: Exchange Announcement | K3: Finance | L3: Large Cap | M3: Completed
A4: 45991 | B4: =EOMONTH(Table1[[#This Row],[Announcement_Date]],0) -> 45991 | C4: Summit Resources | D4: Canada | E4: NASDAQ | F4: =CONCATENATE(D4,"-",E4) -> Canada-NASDAQ | G4: Stock Split | H4: ID828074 | I4: ISIN | J4: Press Release | K4: Finance | L4: Mid Cap | M4: Completed
A5: 45885 | B5: =EOMONTH(Table1[[#This Row],[Announcement_Date]],0) -> 45900 | C5: Evergreen Foods | D5: Canada | E5: NYSE | F5: =CONCATENATE(D5,"-",E5) -> Canada-NYSE | G5: Rights Issue | H5: ID667668 | I5: CUSIP | J5: Regulatory Filing | K5: Telecommunications | L5: Large Cap | M5: Completed
A6: 45983 | B6: =EOMONTH(Table1[[#This Row],[Announcement_Date]],0) -> 45991 | C6: Nova Materials | D6: Canada | E6: NASDAQ | F6: =CONCATENATE(D6,"-",E6) -> Canada-NASDAQ | G6: Stock Split | H6: ID622495 | I6: SEDOL | J6: Press Release | K6: Energy | L6: Small Cap | M6: Announced
A7: 45957 | B7: =EOMONTH(Table1[[#This Row],[Announcement_Date]],0) -> 45961 | C7: Quantum Pharma | D7: USA | E7: TSX | F7: =CONCATENATE(D7,"-",E7) -> USA-TSX | G7: Tender Offer | H7: ID509329 | I7: ISIN | J7: Exchange Announcement | K7: Consumer Goods | L7: Large Cap | M7: Announced
A8: 46027 | B8: =EOMONTH(Table1[[#This Row],[Announcement_Date]],0) -> 46053 | C8: Silverline Industries | D8: Canada | E8: NYSE | F8: =CONCATENATE(D8,"-",E8) -> Canada-NYSE | G8: Dividend | H8: ID136180 | I8: ISIN | J8: Press Release | K8: Technology | L8: Large Cap | M8: Announced
A9: 45803 | B9: =EOMONTH(Table1[[#This Row],[Announcement_Date]],0) -> 45808 | C9: Orion Aerospace | D9: Canada | E9: TSX | F9: =CONCATENATE(D9,"-",E9) -> Canada-TSX | G9: Tender Offer | H9: ID577662 | I9: ISIN | J9: Press Release | K9: Healthcare | L9: Small Cap | M9: Announced
A10: 45787 | B10: =EOMONTH(Table1[[#This Row],[Announcement_Date]],0) -> 45808 | C10: Pacific Motors | D10: USA | E10: TSX | F10: =CONCATENATE(D10,"-",E10) -> USA-TSX | G10: Rights Issue | H10: ID531241 | I10: CUSIP | J10: Exchange Announcement | K10: Telecommunications | L10: Small Cap | M10: Confirmed
A11: 45887 | B11: =EOMONTH(Table1[[#This Row],[Announcement_Date]],0) -> 45900 | C11: Maple Finance | D11: Canada | E11: NYSE | F11: =CONCATENATE(D11,"-",E11) -> Canada-NYSE | G11: Spin-off | H11: ID509418 | I11: CUSIP | J11: Press Release | K11: Healthcare | L11: Mid Cap | M11: Announced
A12: 45907 | B12: =EOMONTH(Table1[[#This Row],[Announcement_Date]],0) -> 45930 | C12: Evergreen Foods | D12: USA | E12: NASDAQ | F12: =CONCATENATE(D12,"-",E12) -> USA-NASDAQ | G12: Dividend | H12: ID837386 | I12: CUSIP | J12: Exchange Announcement | K12: Technology | L12: Large Cap | M12: Confirmed
A13: 46111 | B13: =EOMONTH(Table1[[#This Row],[Announcement_Date]],0) -> 46112 | C13: Quantum Pharma | D13: USA | E13: TSX | F13: =CONCATENATE(D13,"-",E13) -> USA-TSX | G13: Dividend | H13: ID323880 | I13: SEDOL | J13: Regulatory Filing | K13: Healthcare | L13: Mid Cap | M13: Completed
... A251: 46002 | B251: =EOMONTH(Table1[[#This Row],[Announcement_Date]],0) -> 46022 | C251: BlueWave Logistics | D251: USA | E251: TSX | F251: =CONCATENATE(D251,"-",E251) -> USA-TSX | G251: Spin-off | H251: ID616370 | I251: SEDOL | J251: Regulatory Filing | K251: Industrials | L251: Large Cap | M251: Announced

Sheet KPI

Sheet Pivot
A2: Row Labels | B2: Count of Event_Type
A3: 2025
A4: Apr | B4: 17
A5: May | B5: 24
A6: Jun | B6: 23
A7: Jul | B7: 22
A8: Aug | B8: 25
A9: Sep | B9: 19
A10: Oct | B10: 28
A11: Nov | B11: 12
A12: Dec | B12: 14
A13: 2026
A14: Jan | B14: 22
A15: Feb | B15: 23 | Q15: x`x
A16: Mar | B16: 21
A17: Grand Total | B17: 250
A20: Row Labels | B20: Count of Event_Type
A21: Consumer Goods | B21: 40
A22: Industrials | B22: 37
A23: Finance | B23: 36
A24: Energy | B24: 35
A25: Telecommunications | B25: 35
A26: Healthcare | B26: 34
A27: Technology | B27: 33
A28: Grand Total | B28: 250
A34: Row Labels | B34: Count of Event_Type
A35: Tender Offer | B35: 45
A36: Rights Issue | B36: 45
A37: Dividend | B37: 43
A38: Merger & Acquisition | B38: 41
A39: Stock Split | B39: 40
A40: Spin-off | B40: 36
A41: Grand Total | B41: 250
A49: Row Labels | B49: Count of Event_Type
A50: Canada | B50: 131
A51: USA | B51: 119
A52: Grand Total | B52: 250
A63: Row Labels | B63: Count of Event_Type
A64: Large Cap | B64: 96
A65: Mid Cap | B65: 81
...

Sheet Dashboard
A1: Corporate Actions Dashboard
Q20: x`

Sheet KPI Summary
A1: KPI | B1: Value
A2: Total Corporate Actions | B2: =COUNTA(Corporate_Actions_Data!A2:A251) -> 250
A3: Total Companies | B3: =COUNTA(_xlfn.UNIQUE(Corporate_Actions_Data!C2:C251)) -> 15
A4: Most Frequent Event Type | B4: Rights Issue & Tender Offer
A5: Events this Month | B5: =COUNTIFS(Corporate_Actions_Data!A2:A251, ">=" & EOMONTH(TODAY(),-1) + 1,Corporate_Actions_Data!A2:A251, "<=" & EOMONTH(TODAY(),0)) -> 0
A6: Unique Markets Covered | B6: =COUNTA(_xlfn.UNIQUE(Corporate_Actions_Data!D2:D251)) -> 2 | C6: =COUNTA(_xlfn.UNIQUE(Corporate_Actions_Data!E2:E251)) -> 3 | D6: =COUNTA(_xlfn.UNIQUE(Corporate_Actions_Data!F2:F251)) -> 6 | E6: {=COUNTA(_xlfn.UNIQUE(Corporate_Actions_Data!D2:D251 & "-" & Corporate_Actions_Data!E2:E251))} -> 6
